Workbook

Sheet 📋 Kapak
B3: THE GOVERNANCE
B4: Kurumsal Risk & Teknoloji Yönetişimi · thegovernance.com.tr
B8: KVKK UYUM KONTROL LİSTESİ
B9: Kişisel Verilerin Korunması Kanunu — Kurumsal Uyum Değerlendirme Aracı
B12: Hazırlayan | D12: The Governance Editörü
B14: Versiyon | D14: v1.0 — Mayıs 2026
B16: Hukuki Dayanak | D16: 6698 sayılı KVKK + Üretken AI Rehberi (Kasım 2025)
B18: Hedef Kitle | D18: Uyum Ekipleri · İç Denetim · Risk Yönetimi · KVKK Koordinatörü
B20: Kullanım | D20: Yıllık uyum değerlendirmesi, iç denetim hazırlığı, gap analizi
B25: NASIL KULLANILIR?
B26: 1️⃣ 'Değerlendirme' sekmesine geçin — her madde için Evet / Hayır / Kısmen seçin
B27: 2️⃣ 'Açıklama / Kanıt' sütununa mevcut uygulamanızı veya belge referansını yazın
B28: 3️⃣ 'Sorumlu' sütununa ilgili departman veya kişiyi atayın
B29: 4️⃣ 'Gösterge Paneli' sekmesinden genel uyum skorunuzu ve risk haritanızı görün
B30: 5️⃣ 'Aksiyon Planı' sekmesine Hayır / Kısmen yanıtları için aksiyon girin
B33: ⚠ Hukuki Uyarı
B34: Bu araç, genel bilgilendirme ve iç değerlendirme amacıyla hazırlanmıştır. Hukuki tavsiye niteliği taşımaz. Kurumunuza özel uyum stratejisi için hukuk danışmanı ve KVKK uzmanından destek almanız önerilir. © 2026 The Governance — thegovernance.com.tr

Sheet ✅ Değerlendirme
A1: THE GOVERNANCE · KVKK UYUM KONTROL LİSTESİ · Değerlendirme Formu
A2: Her madde için Uyum Durumu sütunundan seçim yapın · Açıklama ve Sorumlu alanlarını doldurun
A4: # | B4: KATEGORİ | C4: KONTROL MADDESİ | D4: HUKUKI DAYANAK | E4: UYUM DURUMU | F4: AÇIKLAMA / KANIT | G4: SORUMLU | H4: SON TARİH | I4: ÖNCELİK | J4: RİSK SEVİYESİ | K4: NOTLAR | L4: SON GÜNCELLEME
A5: ▸ VERİ ENVANTERİ
A6: 1 | B6: VERİ ENVANTERİ | C6: Kişisel veri envanteri (VERBİS kaydı) güncel ve eksiksiz mi? | D6: KVKK Md.16 / VERBİS Yön. | I6: Kritik | J6: Yüksek
A7: 2 | B7: VERİ ENVANTERİ | C7: İşlenen her kişisel veri kategorisi için hukuki dayanak belirlenmiş mi? | D7: KVKK Md.5-6 | I7: Kritik | J7: Yüksek
A8: 3 | B8: VERİ ENVANTERİ | C8: Özel nitelikli kişisel veriler (sağlık, biyometrik vb.) ayrıca sınıflandırılmış mı? | D8: KVKK Md.6 | I8: Kritik | J8: Yüksek
A9: 4 | B9: VERİ ENVANTERİ | C9: Veri saklama süreleri politikaya bağlanmış ve uygulanıyor mu? | D9: KVKK Md.7 / Silinme Yön. | I9: Yüksek | J9: Yüksek
A10: 5 | B10: VERİ ENVANTERİ | C10: Veri akış haritaları (data flow map) hazırlanmış mı? | D10: GDPR Art.30 uyum | I10: Orta | J10: Orta
A11: ▸ AYDINLATMA
A12: 6 | B12: AYDINLATMA | C12: Çalışanlara yönelik aydınlatma metni mevcut ve güncel mi? | D12: KVKK Md.10 | I12: Kritik | J12: Yüksek
A13: 7 | B13: AYDINLATMA | C13: Müşterilere yönelik aydınlatma metni web sitesinde erişilebilir mi? | D13: KVKK Md.10 | I13: Kritik | J13: Yüksek
A14: 8 | B14: AYDINLATMA | C14: Aydınlatma metinleri sade, anlaşılır dilde yazılmış mı? | D14: KVKK Kılavuz | I14: Orta | J14: Orta
A15: 9 | B15: AYDINLATMA | C15: Tedarikçi/iş ortağı aydınlatma metinleri mevcut mu? | D15: KVKK Md.10 | I15: Yüksek | J15: Orta
A16: ▸ AÇIK RIZA
A17: 10 | B17: AÇIK RIZA | C17: Rıza gerektiren işlemler için ayrı, açık rıza metinleri var mı? | D17: KVKK Md.3,5 | I17: Kritik | J17: Yüksek
A18: 11 | B18: AÇIK RIZA | C18: Rızalar özgür iradeyle alınıyor mu (hizmet şartına bağlı değil mi)? | D18: KVKK Md.3 | I18: Kritik | J18: Yüksek
A19: 12 | B19: AÇIK RIZA | C19: Rıza geri çekme mekanizması kolay erişilebilir mi? | D19: KVKK Md.11 | I19: Yüksek | J19: Yüksek
A20: 13 | B20: AÇIK RIZA | C20: Pazarlama rızaları ayrı toplanıyor mu? | D20: KVKK Md.5 | I20: Yüksek | J20: Orta
A21: ▸ VERİ GÜVENLİĞİ
A22: 14 | B22: VERİ GÜVENLİĞİ | C22: Teknik güvenlik önlemleri belgelenmiş mi? (şifreleme, erişim kontrolü vb.) | D22: KVKK Md.12 | I22: Kritik | J22: Yüksek
A23: 15 | B23: VERİ GÜVENLİĞİ | C23: İdari güvenlik tedbirleri (politikalar, eğitimler) uygulanıyor mu? | D23: KVKK Md.12 | I23: Kritik | J23: Yüksek
A24: 16 | B24: VERİ GÜVENLİĞİ | C24: Veri ihlali müdahale planı (VIMP) hazırlanmış ve test edilmiş mi? | D24: KVKK Md.12 | I24: Kritik | J24: Yüksek
A25: 17 | B25: VERİ GÜVENLİĞİ | C25: Veri ihlali durumunda 72 saat içinde bildirim prosedürü var mı? | D25: KVKK Md.12 / Bildirim Yön. | I25: Kritik | J25: Yüksek
A26: 18 | B26: VERİ GÜVENLİĞİ | C26: Erişim yetkileri düzenli gözden geçiriliyor mu? | D26: KVKK Md.12 | I26: Yüksek | J26: Yüksek
A27: 19 | B27: VERİ GÜVENLİĞİ | C27: Üçüncü taraf güvenlik testleri (penetrasyon testi) yapılıyor mu? | D27: KVKK Md.12 | I27: Orta | J27: Orta
A28: ▸ VERİ AKTARIMI
A29: 20 | B29: VERİ AKTARIMI | C29: Yurt içi veri aktarımlarında hukuki dayanak belirlenmiş mi? | D29: KVKK Md.8 | I29: Kritik | J29: Yüksek
A30: 21 | B30: VERİ AKTARIMI | C30: Yurt dışı veri aktarımı için KVKK Kurulu kararı veya taahhütname var mı? | D30: KVKK Md.9 | I30: Kritik | J30: Yüksek
A31: 22 | B31: VERİ AKTARIMI | C31: Bulut hizmet sağlayıcılarıyla veri işleme sözleşmesi imzalanmış mı? | D31: KVKK Md.8-9 | I31: Kritik | J31: Yüksek
A32: 23 | B32: VERİ AKTARIMI | C32: Yapay zeka platformlarına (ChatGPT vb.) veri aktarımı değerlendirilmiş mi? | D32: KVKK AI Rehberi 2025 | I32: Kritik | J32: Yüksek
A33: 24 | B33: VERİ AKTARIMI | C33: AI araçlarına aktarılan veriler için hukuki dayanak belirlenmiş mi? | D33: KVKK AI Rehberi 2025 Md.4-5 | I33: Kritik | J33: Yüksek
A34: ▸ İLGİLİ KİŞİ HAKLARI
A35: 25 | B35: İLGİLİ KİŞİ HAKLARI | C35: İlgili kişi başvuru formu/kanalı aktif ve erişilebilir mi? | D35: KVKK Md.11 | I35: Kritik | J35: Yüksek
A36: 26 | B36: İLGİLİ KİŞİ HAKLARI | C36: Başvurulara 30 gün içinde yanıt verme prosedürü işliyor mu? | D36: KVKK Md.13 | I36: Kritik | J36: Yüksek
A37: 27 | B37: İLGİLİ KİŞİ HAKLARI | C37: Silme/anonimleştirme talepleri için teknik altyapı hazır mı? | D37: KVKK Md.7,11 | I37: Yüksek | J37: Yüksek
A38: 28 | B38: İLGİLİ KİŞİ HAKLARI | C38: İlgili kişi başvuruları kayıt altına alınıyor mu? | D38: KVKK Md.13 | I38: Yüksek | J38: Orta
A39: ▸ KURUM İÇİ YÖNETİŞİM
A40: 29 | B40: KURUM İÇİ YÖNETİŞİM | C40: KVKK Koordinatörü / DPO atanmış mı? | D40: KVKK Md.12 | I40: Kritik | J40: Yüksek
A41: 30 | B41: KURUM İÇİ YÖNETİŞİM | C41: Çalışan KVKK farkındalık eğitimi yıllık yapılıyor mu? | D41: KVKK Md.12 | I41: Yüksek | J41: Orta
...

Sheet 📊 Gösterge Paneli
A1: THE GOVERNANCE · KVKK UYUM SKORU GÖSTERGESİ
A2: Değerlendirme sekmesindeki yanıtlarınıza göre otomatik hesaplanır
A4: TOPLAM MADDE | D4: ✅ EVET | G4: ⚠️ KISMİ | J4: ❌ HAYIR
A5: =COUNTA('✅ Değerlendirme'!C5:C44) | D5: =COUNTIF('✅ Değerlendirme'!E5:E44,"✅ Evet") | G5: =COUNTIF('✅ Değerlendirme'!E5:E44,"⚠️ Kısmen") | J5: =COUNTIF('✅ Değerlendirme'!E5:E44,"❌ Hayır")
A9: GENEL UYUM SKORU | F9: KATEGORİ BAZLI DURUM
A10: =IFERROR(TEXT(COUNTIF('✅ Değerlendirme'!E5:E44,"✅ Evet")/COUNTA('✅ Değerlendirme'!E5:E44),"0%"),"—") | F10: Veri Envanteri | J10: =COUNTIF('✅ Değerlendirme'!E6:E10,"✅ Evet") | K10: =COUNTIF('✅ Değerlendirme'!E6:E10,"⚠️ Kısmen") | L10: =COUNTIF('✅ Değerlendirme'!E6:E10,"❌ Hayır")
F11: Aydınlatma | J11: =COUNTIF('✅ Değerlendirme'!E12:E15,"✅ Evet") | K11: =COUNTIF('✅ Değerlendirme'!E12:E15,"⚠️ Kısmen") | L11: =COUNTIF('✅ Değerlendirme'!E12:E15,"❌ Hayır")
F12: Açık Rıza | J12: =COUNTIF('✅ Değerlendirme'!E17:E20,"✅ Evet") | K12: =COUNTIF('✅ Değerlendirme'!E17:E20,"⚠️ Kısmen") | L12: =COUNTIF('✅ Değerlendirme'!E17:E20,"❌ Hayır")
F13: Veri Güvenliği | J13: =COUNTIF('✅ Değerlendirme'!E22:E27,"✅ Evet") | K13: =COUNTIF('✅ Değerlendirme'!E22:E27,"⚠️ Kısmen") | L13: =COUNTIF('✅ Değerlendirme'!E22:E27,"❌ Hayır")
F14: Veri Aktarımı | J14: =COUNTIF('✅ Değerlendirme'!E29:E33,"✅ Evet") | K14: =COUNTIF('✅ Değerlendirme'!E29:E33,"⚠️ Kısmen") | L14: =COUNTIF('✅ Değerlendirme'!E29:E33,"❌ Hayır")
F15: İlgili Kişi Hakları | J15: =COUNTIF('✅ Değerlendirme'!E35:E38,"✅ Evet") | K15: =COUNTIF('✅ Değerlendirme'!E35:E38,"⚠️ Kısmen") | L15: =COUNTIF('✅ Değerlendirme'!E35:E38,"❌ Hayır")
F16: Kurum İçi Yönetişim | J16: =COUNTIF('✅ Değerlendirme'!E40:E44,"✅ Evet") | K16: =COUNTIF('✅ Değerlendirme'!E40:E44,"⚠️ Kısmen") | L16: =COUNTIF('✅ Değerlendirme'!E40:E44,"❌ Hayır")

Sheet 🎯 Aksiyon Planı
A1: THE GOVERNANCE · KVKK UYUM AKSİYON PLANI
A2: Hayır veya Kısmen yanıtlanan maddeler için aksiyon, sorumlu ve takvim girin
A3: # | B3: KATEGORİ | C3: KONTROL MADDESİ | D3: GAP / SORUN | E3: AKSİYON PLANI | F3: SORUMLU | G3: BAŞLANGIÇ | H3: BİTİŞ | I3: DURUM | J3: NOTLAR
A4: 1
A5: 2
A6: 3
A7: 4
A8: 5
A9: 6
A10: 7
A11: 8
A12: 9
A13: 10
A14: 11
A15: 12
... A18: 15

Sheet 📚 Referans
A1: THE GOVERNANCE · KVKK YASAL REFERANS KILAVUZU
A4: TÜR | B4: KAYNAK | C4: AÇIKLAMA | D4: ERİŞİM
A5: MEVZUAT | B5: 6698 Sayılı KVKK | C5: Ana kanun — tüm kişisel veri işleme faaliyetlerinin dayanağı | D5: https://www.mevzuat.gov.tr
A6: MEVZUAT | B6: VERBİS Yönetmeliği | C6: Veri Sorumluları Sicil Bilgi Sistemi kaydı zorunluluğu | D6: https://verbis.kvkk.gov.tr
A7: MEVZUAT | B7: Silme, Yok Etme ve Anonimleştirme Yönetmeliği | C7: Saklama süreleri ve imha yükümlülükleri | D7: https://www.kvkk.gov.tr
A8: KILAVUZ | B8: Üretken Yapay Zekâ Rehberi (Kasım 2025) | C8: AI platformlarına veri aktarımında uyum çerçevesi | D8: https://www.kvkk.gov.tr
A9: KILAVUZ | B9: Aydınlatma Yükümlülüğü Rehberi | C9: Aydınlatma metni hazırlama kılavuzu | D9: https://www.kvkk.gov.tr
A10: KILAVUZ | B10: İlgili Kişi Başvuru Rehberi | C10: Başvuru alma, değerlendirme ve yanıt prosedürleri | D10: https://www.kvkk.gov.tr
A11: STANDART | B11: ISO/IEC 27701:2019 | C11: Gizlilik bilgi yönetim sistemi standardı — KVKK uyumunu destekler | D11: https://www.iso.org
A12: STANDART | B12: ISO/IEC 27001:2022 | C12: Bilgi güvenliği yönetim sistemi — teknik güvenlik altyapısı | D12: https://www.iso.org
A13: AB MEVZUAT | B13: GDPR (2016/679) | C13: AB Genel Veri Koruma Tüzüğü — AB ile iş yapan firmalar için | D13: https://gdpr-info.eu
A14: AB MEVZUAT | B14: AB AI Act | C14: Yapay zeka sistemleri için AB düzenlemesi — 2026 uyum takvimi | D14: https://artificialintelligenceact.eu
